Workbook

Sheet Student Details
B2: Name | C2: Shreya Khubber
B3: ID | C3: 2020A8PS1807P
B4: PS Station: | C4: Morningstar

Sheet Horizontal Analysis - Allcargo
A1: Horizontal Analysis of the Income Statement
A3: In Millions of INR except Per Share | B3: FY 2018 | C3: FY 2019 | D3: FY 2020 | E3: FY 2021 | F3: FY 2022 | G3: FY 2023 | J3: In Millions of INR except Per Share | K3: FY 2019 | L3: FY 2020 | M3: FY 2021 | N3: FY 2022 | O3: FY 2023
A4: 12 Months Ending | B4: 03/31/2018 | C4: 03/31/2019 | D4: 03/31/2020 | E4: 03/31/2021 | F4: 03/31/2022 | G4: 03/31/2023 | J4: 12 Months Ending | K4: 03/31/2019 | L4: 03/31/2020 | M4: 03/31/2021 | N4: 03/31/2022 | O4: 03/31/2023
A5: Revenue | B5: 60335.4 | C5: 68814.1 | D5: 73387 | E5: 104884.5 | F5: 190620.7 | G5: 180507.7 | J5: Revenue | K5: =IFERROR((C5/$C5)*100, "") -> 100 | L5: =IFERROR((D5/$C5)*100, "") -> 106.6453 | M5: =IFERROR((E5/$C5)*100, "") -> 152.41716 | N5: =IFERROR((F5/$C5)*100, "") -> 277.0082 | O5: =IFERROR((G5/$C5)*100, "") -> 262.31208
A6: + Sales & Services Revenue | B6: 60335.4 | C6: 68814.1 | D6: 73387 | E6: 104884.5 | F6: 190620.7 | G6: 180507.7 | J6: + Sales & Services Revenue | K6: =IFERROR((C6/$C6)*100, "") -> 100 | L6: =IFERROR((D6/$C6)*100, "") -> 106.6453 | M6: =IFERROR((E6/$C6)*100, "") -> 152.41716 | N6: =IFERROR((F6/$C6)*100, "") -> 277.0082 | O6: =IFERROR((G6/$C6)*100, "") -> 262.31208
A7: + Other Operating Income | B7: 156.5 | C7: 134.5 | D7: 75.4 | E7: 96.5 | F7: 0 | G7: 0 | J7: + Other Operating Income | K7: =IFERROR((C7/$C7)*100, "") -> 100 | L7: =IFERROR((D7/$C7)*100, "") -> 56.05948 | M7: =IFERROR((E7/$C7)*100, "") -> 71.747212 | N7: =IFERROR((F7/$C7)*100, "") -> 0 | O7: =IFERROR((G7/$C7)*100, "") -> 0
A8: - Operating Expenses | B8: 58311.2 | C8: 66022.8 | D8: 70689.2 | E8: 100706.6 | F8: 179578.1 | G8: 171319.9 | J8: - Operating Expenses | K8: =IFERROR((C8/$C8)*100, "") -> 100 | L8: =IFERROR((D8/$C8)*100, "") -> 107.06786 | M8: =IFERROR((E8/$C8)*100, "") -> 152.53306 | N8: =IFERROR((F8/$C8)*100, "") -> 271.99407 | O8: =IFERROR((G8/$C8)*100, "") -> 259.48597
A9: + Selling, General & Admin | B9: — | C9: — | D9: — | E9: — | F9: — | G9: — | J9: + Selling, General & Admin | K9: =IFERROR((C9/$C9)*100, "") | L9: =IFERROR((D9/$C9)*100, "") | M9: =IFERROR((E9/$C9)*100, "") | N9: =IFERROR((F9/$C9)*100, "") | O9: =IFERROR((G9/$C9)*100, "")
A10: + Selling & Marketing | B10: 282.3 | C10: 248.1 | D10: 264.4 | E10: 117.2 | F10: 0 | G10: 47.8 | J10: + Selling & Marketing | K10: =IFERROR((C10/$C10)*100, "") -> 100 | L10: =IFERROR((D10/$C10)*100, "") -> 106.56993 | M10: =IFERROR((E10/$C10)*100, "") -> 47.239017 | N10: =IFERROR((F10/$C10)*100, "") -> 0 | O10: =IFERROR((G10/$C10)*100, "") -> 19.266425
A11: + Research & Development | B11: 0 | C11: 0 | D11: 0 | E11: 0 | F11: — | G11: — | J11: + Research & Development | K11: =IFERROR((C11/$C11)*100, "") | L11: =IFERROR((D11/$C11)*100, "") | M11: =IFERROR((E11/$C11)*100, "") | N11: =IFERROR((F11/$C11)*100, "") | O11: =IFERROR((G11/$C11)*100, "")
A12: + Depreciation & Amortization | B12: 1590.6 | C12: 1559.3 | D12: 2316 | E12: 3060.9 | F12: 2375.7 | G12: 2780.1 | J12: + Depreciation & Amortization | K12: =IFERROR((C12/$C12)*100, "") -> 100 | L12: =IFERROR((D12/$C12)*100, "") -> 148.52819 | M12: =IFERROR((E12/$C12)*100, "") -> 196.29962 | N12: =IFERROR((F12/$C12)*100, "") -> 152.35683 | O12: =IFERROR((G12/$C12)*100, "") -> 178.29154
A13: + Prov For Doubtful Accts | B13: 298.1 | C13: -108.8 | D13: 161.8 | E13: 318.4 | F13: — | G13: — | J13: + Prov For Doubtful Accts | K13: =IFERROR((C13/$C13)*100, "") -> 100 | L13: =IFERROR((D13/$C13)*100, "") -> -148.71324 | M13: =IFERROR((E13/$C13)*100, "") -> -292.64706 | N13: =IFERROR((F13/$C13)*100, "") | O13: =IFERROR((G13/$C13)*100, "")
A14: + Other Operating Expense | B14: 56140.2 | C14: 64324.2 | D14: 67947 | E14: 97210.1 | F14: 177202.4 | G14: 168492 | J14: + Other Operating Expense | K14: =IFERROR((C14/$C14)*100, "") -> 100 | L14: =IFERROR((D14/$C14)*100, "") -> 105.63209 | M14: =IFERROR((E14/$C14)*100, "") -> 151.12524 | N14: =IFERROR((F14/$C14)*100, "") -> 275.48326 | O14: =IFERROR((G14/$C14)*100, "") -> 261.94185
A15: Operating Income (Loss) | B15: 2180.7 | C15: 2925.8 | D15: 2773.2 | E15: 4274.4 | F15: 11042.6 | G15: 9187.8 | J15: Operating Income (Loss) | K15: =IFERROR((C15/$C15)*100, "") -> 100 | L15: =IFERROR((D15/$C15)*100, "") -> 94.784332 | M15: =IFERROR((E15/$C15)*100, "") -> 146.09338 | N15: =IFERROR((F15/$C15)*100, "") -> 377.42156 | O15: =IFERROR((G15/$C15)*100, "") -> 314.02693
A16: - Non-Operating (Income) Loss | B16: 60.3 | C16: 99.9 | D16: -151.1 | E16: 2788.1 | F16: -143.2 | G16: -121.3 | J16: - Non-Operating (Income) Loss | K16: =IFERROR((C16/$C16)*100, "") -> 100 | L16: =IFERROR((D16/$C16)*100, "") -> -151.25125 | M16: =IFERROR((E16/$C16)*100, "") -> 2790.8909 | N16: =IFERROR((F16/$C16)*100, "") -> -143.34334 | O16: =IFERROR((G16/$C16)*100, "") -> -121.42142
A17: + Interest Expense, Net | B17: -20.2 | C17: -41.9 | D17: 3.3 | E17: 877 | F17: 162.3 | G17: -29.2 | J17: + Interest Expense, Net | K17: =IFERROR((C17/$C17)*100, "") -> 100 | L17: =IFERROR((D17/$C17)*100, "") -> -7.875895 | M17: =IFERROR((E17/$C17)*100, "") -> -2093.0788 | N17: =IFERROR((F17/$C17)*100, "") -> -387.35084 | O17: =IFERROR((G17/$C17)*100, "") -> 69.689737
A18: + Interest Expense | B18: 6 | C18: 2.5 | D18: 3.3 | E18: 980.9 | F18: 327.8 | G18: 243.7 | J18: + Interest Expense | K18: =IFERROR((C18/$C18)*100, "") -> 100 | L18: =IFERROR((D18/$C18)*100, "") -> 132 | M18: =IFERROR((E18/$C18)*100, "") -> 39236 | N18: =IFERROR((F18/$C18)*100, "") -> 13112 | O18: =IFERROR((G18/$C18)*100, "") -> 9748
A19: - Interest Income | B19: 26.2 | C19: 44.4 | D19: 0 | E19: 103.9 | F19: 165.5 | G19: 272.9 | J19: - Interest Income | K19: =IFERROR((C19/$C19)*100, "") -> 100 | L19: =IFERROR((D19/$C19)*100, "") -> 0 | M19: =IFERROR((E19/$C19)*100, "") -> 234.00901 | N19: =IFERROR((F19/$C19)*100, "") -> 372.74775 | O19: =IFERROR((G19/$C19)*100, "") -> 614.63964
A20: + Other Investment (Inc) Loss | B20: — | C20: — | D20: — | E20: -8 | F20: -1.9 | G20: -16 | J20: + Other Investment (Inc) Loss | K20: =IFERROR((C20/$C20)*100, "") | L20: =IFERROR((D20/$C20)*100, "") | M20: =IFERROR((E20/$C20)*100, "") | N20: =IFERROR((F20/$C20)*100, "") | O20: =IFERROR((G20/$C20)*100, "")
A21: + Foreign Exch (Gain) Loss | B21: -2.2 | C21: -13.7 | D21: 0 | E21: 0 | F21: 0 | G21: -47.7 | J21: + Foreign Exch (Gain) Loss | K21: =IFERROR((C21/$C21)*100, "") -> 100 | L21: =IFERROR((D21/$C21)*100, "") -> 0 | M21: =IFERROR((E21/$C21)*100, "") -> 0 | N21: =IFERROR((F21/$C21)*100, "") -> 0 | O21: =IFERROR((G21/$C21)*100, "") -> 348.17518
A22: + (Income) Loss from Affiliates | B22: -48 | C22: -52.1 | D22: -60.7 | E22: -170 | F22: -812 | G22: -174.4 | J22: + (Income) Loss from Affiliates | K22: =IFERROR((C22/$C22)*100, "") -> 100 | L22: =IFERROR((D22/$C22)*100, "") -> 116.50672 | M22: =IFERROR((E22/$C22)*100, "") -> 326.29559 | N22: =IFERROR((F22/$C22)*100, "") -> 1558.5413 | O22: =IFERROR((G22/$C22)*100, "") -> 334.74088
A23: + Other Non-Op (Income) Loss | B23: 130.7 | C23: 207.6 | D23: -93.7 | E23: 2089.1 | F23: 508.4 | G23: 146 | J23: + Other Non-Op (Income) Loss | K23: =IFERROR((C23/$C23)*100, "") -> 100 | L23: =IFERROR((D23/$C23)*100, "") -> -45.134875 | M23: =IFERROR((E23/$C23)*100, "") -> 1006.3102 | N23: =IFERROR((F23/$C23)*100, "") -> 244.89403 | O23: =IFERROR((G23/$C23)*100, "") -> 70.327553
A24: Pretax Income (Loss), Adjusted | B24: 2120.4 | C24: 2825.9 | D24: 2924.3 | E24: 1486.3 | F24: 11185.8 | G24: 9309.1 | J24: Pretax Income (Loss), Adjusted | K24: =IFERROR((C24/$C24)*100, "") -> 100 | L24: =IFERROR((D24/$C24)*100, "") -> 103.48208 | M24: =IFERROR((E24/$C24)*100, "") -> 52.595633 | N24: =IFERROR((F24/$C24)*100, "") -> 395.83142 | O24: =IFERROR((G24/$C24)*100, "") -> 329.42072
A25: - Abnormal Losses (Gains) | B25: -131.8 | C25: -194.9 | D25: -130.1 | E25: -104.5 | F25: 375.1 | G25: 355.7 | J25: - Abnormal Losses (Gains) | K25: =IFERROR((C25/$C25)*100, "") -> 100 | L25: =IFERROR((D25/$C25)*100, "") -> 66.752181 | M25: =IFERROR((E25/$C25)*100, "") -> 53.61724 | N25: =IFERROR((F25/$C25)*100, "") -> -192.45767 | O25: =IFERROR((G25/$C25)*100, "") -> -182.50385
A26: + Disposal of Assets | B26: -149.3 | C26: -127.1 | D26: 31.6 | E26: -90.6 | F26: 14.4 | G26: 3.2 | J26: + Disposal of Assets | K26: =IFERROR((C26/$C26)*100, "") -> 100 | L26: =IFERROR((D26/$C26)*100, "") -> -24.862313 | M26: =IFERROR((E26/$C26)*100, "") -> 71.282455 | N26: =IFERROR((F26/$C26)*100, "") -> -11.329662 | O26: =IFERROR((G26/$C26)*100, "") -> -2.5177026
A27: + Asset Write-Down | B27: — | C27: — | D27: — | E27: — | F27: 555.8 | G27: 702.8 | J27: + Asset Write-Down | K27: =IFERROR((C27/$C27)*100, "") | L27: =IFERROR((D27/$C27)*100, "") | M27: =IFERROR((E27/$C27)*100, "") | N27: =IFERROR((F27/$C27)*100, "") | O27: =IFERROR((G27/$C27)*100, "")
A28: + Impairment of Goodwill | B28: 68.6 | C28: — | D28: — | E28: — | F28: — | G28: — | J28: + Impairment of Goodwill | K28: =IFERROR((C28/$C28)*100, "") | L28: =IFERROR((D28/$C28)*100, "") | M28: =IFERROR((E28/$C28)*100, "") | N28: =IFERROR((F28/$C28)*100, "") | O28: =IFERROR((G28/$C28)*100, "")
A29: + Gain/Loss on Sale/Acquisition of Business | B29: — | C29: — | D29: -125.8 | E29: — | F29: -185.1 | G29: -278.7 | J29: + Gain/Loss on Sale/Acquisition of Business | K29: =IFERROR((C29/$C29)*100, "") | L29: =IFERROR((D29/$C29)*100, "") | M29: =IFERROR((E29/$C29)*100, "") | N29: =IFERROR((F29/$C29)*100, "") | O29: =IFERROR((G29/$C29)*100, "")
A30: + Sale of Investments | B30: -51.1 | C30: -67.8 | D30: -35.9 | E30: -13.9 | F30: -6.7 | G30: -50.2 | J30: + Sale of Investments | K30: =IFERROR((C30/$C30)*100, "") -> 100 | L30: =IFERROR((D30/$C30)*100, "") -> 52.949853 | M30: =IFERROR((E30/$C30)*100, "") -> 20.501475 | N30: =IFERROR((F30/$C30)*100, "") -> 9.8820059 | O30: =IFERROR((G30/$C30)*100, "") -> 74.041298
A31: + Unrealized Investments | B31: — | C31: — | D31: — | E31: — | F31: -3.3 | G31: -21.4 | J31: + Unrealized Investments | K31: =IFERROR((C31/$C31)*100, "") | L31: =IFERROR((D31/$C31)*100, "") | M31: =IFERROR((E31/$C31)*100, "") | N31: =IFERROR((F31/$C31)*100, "") | O31: =IFERROR((G31/$C31)*100, "")
A32: + Other Abnormal Items | B32: — | C32: — | D32: — | E32: — | F32: — | G32: — | J32: + Other Abnormal Items | K32: =IFERROR((C32/$C32)*100, "") | L32: =IFERROR((D32/$C32)*100, "") | M32: =IFERROR((E32/$C32)*100, "") | N32: =IFERROR((F32/$C32)*100, "") | O32: =IFERROR((G32/$C32)*100, "")
A33: Pretax Income (Loss), GAAP | B33: 2252.2 | C33: 3020.8 | D33: 3054.4 | E33: 1590.8 | F33: 10810.7 | G33: 8953.4 | J33: Pretax Income (Loss), GAAP | K33: =IFERROR((C33/$C33)*100, "") -> 100 | L33: =IFERROR((D33/$C33)*100, "") -> 101.11229 | M33: =IFERROR((E33/$C33)*100, "") -> 52.661547 | N33: =IFERROR((F33/$C33)*100, "") -> 357.8754 | O33: =IFERROR((G33/$C33)*100, "") -> 296.39168
A34: - Income Tax Expense (Benefit) | B34: 512.6 | C34: 542.4 | D34: 711 | E34: 639.7 | F34: 2570.2 | G34: 2421.3 | J34: - Income Tax Expense (Benefit) | K34: =IFERROR((C34/$C34)*100, "") -> 100 | L34: =IFERROR((D34/$C34)*100, "") -> 131.08407 | M34: =IFERROR((E34/$C34)*100, "") -> 117.93879 | N34: =IFERROR((F34/$C34)*100, "") -> 473.85693 | O34: =IFERROR((G34/$C34)*100, "") -> 446.40487
A35: + Current Income Tax | B35: 602.8 | C35: 925.3 | D35: 1345 | E35: 1267.7 | F35: 2803.3 | G35: 2508.2 | J35: + Current Income Tax | K35: =IFERROR((C35/$C35)*100, "") -> 100 | L35: =IFERROR((D35/$C35)*100, "") -> 145.35826 | M35: =IFERROR((E35/$C35)*100, "") -> 137.00421 | N35: =IFERROR((F35/$C35)*100, "") -> 302.9612 | O35: =IFERROR((G35/$C35)*100, "") -> 271.06884
A36: + Deferred Income Tax | B36: -90.2 | C36: -382.9 | D36: -634 | E36: -628 | F36: -233.1 | G36: -86.9 | J36: + Deferred Income Tax | K36: =IFERROR((C36/$C36)*100, "") -> 100 | L36: =IFERROR((D36/$C36)*100, "") -> 165.57848 | M36: =IFERROR((E36/$C36)*100, "") -> 164.01149 | N36: =IFERROR((F36/$C36)*100, "") -> 60.877514 | O36: =IFERROR((G36/$C36)*100, "") -> 22.695221
A37: + Tax Allowance/Credit | B37: — | C37: — | D37: — | E37: — | F37: — | G37: — | J37: + Tax Allowance/Credit | K37: =IFERROR((C37/$C37)*100, "") | L37: =IFERROR((D37/$C37)*100, "") | M37: =IFERROR((E37/$C37)*100, "") | N37: =IFERROR((F37/$C37)*100, "") | O37: =IFERROR((G37/$C37)*100, "")
A38: - (Income) Loss from Affiliates | B38: — | C38: — | D38: — | E38: — | F38: — | G38: — | J38: - (Income) Loss from Affiliates | K38: =IFERROR((C38/$C38)*100, "") | L38: =IFERROR((D38/$C38)*100, "") | M38: =IFERROR((E38/$C38)*100, "") | N38: =IFERROR((F38/$C38)*100, "") | O38: =IFERROR((G38/$C38)*100, "")
A39: Income (Loss) from Cont Ops | B39: 1739.6 | C39: 2478.4 | D39: 2343.4 | E39: 951.1 | F39: 8240.5 | G39: 6532.1 | J39: Income (Loss) from Cont Ops | K39: =IFERROR((C39/$C39)*100, "") -> 100 | L39: =IFERROR((D39/$C39)*100, "") -> 94.552937 | M39: =IFERROR((E39/$C39)*100, "") -> 38.375565 | N39: =IFERROR((F39/$C39)*100, "") -> 332.49274 | O39: =IFERROR((G39/$C39)*100, "") -> 263.56117
A40: - Net Extraordinary Losses (Gains) | B40: 0 | C40: 0 | D40: 0 | E40: 0 | F40: -1405.4 | G40: 0 | J40: - Net Extraordinary Losses (Gains) | K40: =IFERROR((C40/$C40)*100, "") | L40: =IFERROR((D40/$C40)*100, "") | M40: =IFERROR((E40/$C40)*100, "") | N40: =IFERROR((F40/$C40)*100, "") | O40: =IFERROR((G40/$C40)*100, "")
A41: + Discontinued Operations | B41: 0 | C41: 0 | D41: 0 | E41: 0 | F41: -1405.4 | G41: 0 | J41: + Discontinued Operations | K41: =IFERROR((C41/$C41)*100, "") | L41: =IFERROR((D41/$C41)*100, "") | M41: =IFERROR((E41/$C41)*100, "") | N41: =IFERROR((F41/$C41)*100, "") | O41: =IFERROR((G41/$C41)*100, "")
...

Sheet Vertical Analysis - Allcargo
A1: Vertical Analysis of the Income Statement
A3: In Millions of INR except Per Share | B3: FY 2018 | C3: FY 2019 | D3: FY 2020 | E3: FY 2021 | F3: FY 2022 | G3: FY 2023 | J3: In Millions of INR except Per Share | K3: FY 2019 | L3: FY 2020 | M3: FY 2021 | N3: FY 2022 | O3: FY 2023
A4: 12 Months Ending | B4: 03/31/2018 | C4: 03/31/2019 | D4: 03/31/2020 | E4: 03/31/2021 | F4: 03/31/2022 | G4: 03/31/2023 | J4: 12 Months Ending | K4: 03/31/2019 | L4: 03/31/2020 | M4: 03/31/2021 | N4: 03/31/2022 | O4: 03/31/2023
A5: Revenue | B5: 60335.4 | C5: 68814.1 | D5: 73387 | E5: 104884.5 | F5: 190620.7 | G5: 180507.7 | J5: Revenue | K5: =IFERROR(C5/$C$5*100,"") -> 100 | L5: =IFERROR(D5/$D$5*100,"") -> 100 | M5: =IFERROR(E5/$E$5*100,"") -> 100 | N5: =IFERROR(F5/$F$5*100,"") -> 100 | O5: =IFERROR(G5/$G$5*100,"") -> 100
A6: + Sales & Services Revenue | B6: 60335.4 | C6: 68814.1 | D6: 73387 | E6: 104884.5 | F6: 190620.7 | G6: 180507.7 | J6: + Sales & Services Revenue | K6: =IFERROR(C6/$C$5*100,"") -> 100 | L6: =IFERROR(D6/$D$5*100,"") -> 100 | M6: =IFERROR(E6/$E$5*100,"") -> 100 | N6: =IFERROR(F6/$F$5*100,"") -> 100 | O6: =IFERROR(G6/$G$5*100,"") -> 100
A7: + Other Operating Income | B7: 156.5 | C7: 134.5 | D7: 75.4 | E7: 96.5 | F7: 0 | G7: 0 | J7: + Other Operating Income | K7: =IFERROR(C7/$C$5*100,"") -> 0.19545413 | L7: =IFERROR(D7/$D$5*100,"") -> 0.10274299 | M7: =IFERROR(E7/$E$5*100,"") -> 0.092005968 | N7: =IFERROR(F7/$F$5*100,"") -> 0 | O7: =IFERROR(G7/$G$5*100,"") -> 0
A8: - Operating Expenses | B8: 58311.2 | C8: 66022.8 | D8: 70689.2 | E8: 100706.6 | F8: 179578.1 | G8: 171319.9 | J8: - Operating Expenses | K8: =IFERROR(C8/$C$5*100,"") -> 95.943709 | L8: =IFERROR(D8/$D$5*100,"") -> 96.323872 | M8: =IFERROR(E8/$E$5*100,"") -> 96.016666 | N8: =IFERROR(F8/$F$5*100,"") -> 94.20703 | O8: =IFERROR(G8/$G$5*100,"") -> 94.910023
A9: + Selling, General & Admin | B9: — | C9: — | D9: — | E9: — | F9: — | G9: — | J9: + Selling, General & Admin | K9: =IFERROR(C9/$C$5*100,"") | L9: =IFERROR(D9/$D$5*100,"") | M9: =IFERROR(E9/$E$5*100,"") | N9: =IFERROR(F9/$F$5*100,"") | O9: =IFERROR(G9/$G$5*100,"")
A10: + Selling & Marketing | B10: 282.3 | C10: 248.1 | D10: 264.4 | E10: 117.2 | F10: 0 | G10: 47.8 | J10: + Selling & Marketing | K10: =IFERROR(C10/$C$5*100,"") -> 0.36053658 | L10: =IFERROR(D10/$D$5*100,"") -> 0.36028179 | M10: =IFERROR(E10/$E$5*100,"") -> 0.11174196 | N10: =IFERROR(F10/$F$5*100,"") -> 0 | O10: =IFERROR(G10/$G$5*100,"") -> 0.026480865
A11: + Research & Development | B11: 0 | C11: 0 | D11: 0 | E11: 0 | F11: — | G11: — | J11: + Research & Development | K11: =IFERROR(C11/$C$5*100,"") -> 0 | L11: =IFERROR(D11/$D$5*100,"") -> 0 | M11: =IFERROR(E11/$E$5*100,"") -> 0 | N11: =IFERROR(F11/$F$5*100,"") | O11: =IFERROR(G11/$G$5*100,"")
A12: + Depreciation & Amortization | B12: 1590.6 | C12: 1559.3 | D12: 2316 | E12: 3060.9 | F12: 2375.7 | G12: 2780.1 | J12: + Depreciation & Amortization | K12: =IFERROR(C12/$C$5*100,"") -> 2.26596 | L12: =IFERROR(D12/$D$5*100,"") -> 3.1558723 | M12: =IFERROR(E12/$E$5*100,"") -> 2.918353 | N12: =IFERROR(F12/$F$5*100,"") -> 1.246297 | O12: =IFERROR(G12/$G$5*100,"") -> 1.5401559
A13: + Prov For Doubtful Accts | B13: 298.1 | C13: -108.8 | D13: 161.8 | E13: 318.4 | F13: — | G13: — | J13: + Prov For Doubtful Accts | K13: =IFERROR(C13/$C$5*100,"") -> -0.15810713 | L13: =IFERROR(D13/$D$5*100,"") -> 0.22047502 | M13: =IFERROR(E13/$E$5*100,"") -> 0.30357202 | N13: =IFERROR(F13/$F$5*100,"") | O13: =IFERROR(G13/$G$5*100,"")
A14: + Other Operating Expense | B14: 56140.2 | C14: 64324.2 | D14: 67947 | E14: 97210.1 | F14: 177202.4 | G14: 168492 | J14: + Other Operating Expense | K14: =IFERROR(C14/$C$5*100,"") -> 93.47532 | L14: =IFERROR(D14/$D$5*100,"") -> 92.587243 | M14: =IFERROR(E14/$E$5*100,"") -> 92.682999 | N14: =IFERROR(F14/$F$5*100,"") -> 92.960733 | O14: =IFERROR(G14/$G$5*100,"") -> 93.343386
A15: Operating Income (Loss) | B15: 2180.7 | C15: 2925.8 | D15: 2773.2 | E15: 4274.4 | F15: 11042.6 | G15: 9187.8 | J15: Operating Income (Loss) | K15: =IFERROR(C15/$C$5*100,"") -> 4.2517449 | L15: =IFERROR(D15/$D$5*100,"") -> 3.7788709 | M15: =IFERROR(E15/$E$5*100,"") -> 4.07534 | N15: =IFERROR(F15/$F$5*100,"") -> 5.79297 | O15: =IFERROR(G15/$G$5*100,"") -> 5.0899768
A16: - Non-Operating (Income) Loss | B16: 60.3 | C16: 99.9 | D16: -151.1 | E16: 2788.1 | F16: -143.2 | G16: -121.3 | J16: - Non-Operating (Income) Loss | K16: =IFERROR(C16/$C$5*100,"") -> 0.14517374 | L16: =IFERROR(D16/$D$5*100,"") -> -0.20589478 | M16: =IFERROR(E16/$E$5*100,"") -> 2.6582574 | N16: =IFERROR(F16/$F$5*100,"") -> -0.075123006 | O16: =IFERROR(G16/$G$5*100,"") -> -0.067199349
A17: + Interest Expense, Net | B17: -20.2 | C17: -41.9 | D17: 3.3 | E17: 877 | F17: 162.3 | G17: -29.2 | J17: + Interest Expense, Net | K17: =IFERROR(C17/$C$5*100,"") -> -0.060888684 | L17: =IFERROR(D17/$D$5*100,"") -> 0.0044967092 | M17: =IFERROR(E17/$E$5*100,"") -> 0.83615787 | N17: =IFERROR(F17/$F$5*100,"") -> 0.085142904 | O17: =IFERROR(G17/$G$5*100,"") -> -0.016176595
A18: + Interest Expense | B18: 6 | C18: 2.5 | D18: 3.3 | E18: 980.9 | F18: 327.8 | G18: 243.7 | J18: + Interest Expense | K18: =IFERROR(C18/$C$5*100,"") -> 0.0036329764 | L18: =IFERROR(D18/$D$5*100,"") -> 0.0044967092 | M18: =IFERROR(E18/$E$5*100,"") -> 0.93521922 | N18: =IFERROR(F18/$F$5*100,"") -> 0.17196453 | O18: =IFERROR(G18/$G$5*100,"") -> 0.13500809
A19: - Interest Income | B19: 26.2 | C19: 44.4 | D19: 0 | E19: 103.9 | F19: 165.5 | G19: 272.9 | J19: - Interest Income | K19: =IFERROR(C19/$C$5*100,"") -> 0.064521661 | L19: =IFERROR(D19/$D$5*100,"") -> 0 | M19: =IFERROR(E19/$E$5*100,"") -> 0.099061348 | N19: =IFERROR(F19/$F$5*100,"") -> 0.086821631 | O19: =IFERROR(G19/$G$5*100,"") -> 0.15118469
A20: + Other Investment (Inc) Loss | B20: — | C20: — | D20: — | E20: -8 | F20: -1.9 | G20: -16 | J20: + Other Investment (Inc) Loss | K20: =IFERROR(C20/$C$5*100,"") | L20: =IFERROR(D20/$D$5*100,"") | M20: =IFERROR(E20/$E$5*100,"") -> -0.0076274378 | N20: =IFERROR(F20/$F$5*100,"") -> -0.0009967438 | O20: =IFERROR(G20/$G$5*100,"") -> -0.0088638878
A21: + Foreign Exch (Gain) Loss | B21: -2.2 | C21: -13.7 | D21: 0 | E21: 0 | F21: 0 | G21: -47.7 | J21: + Foreign Exch (Gain) Loss | K21: =IFERROR(C21/$C$5*100,"") -> -0.019908711 | L21: =IFERROR(D21/$D$5*100,"") -> 0 | M21: =IFERROR(E21/$E$5*100,"") -> 0 | N21: =IFERROR(F21/$F$5*100,"") -> 0 | O21: =IFERROR(G21/$G$5*100,"") -> -0.026425466
A22: + (Income) Loss from Affiliates | B22: -48 | C22: -52.1 | D22: -60.7 | E22: -170 | F22: -812 | G22: -174.4 | J22: + (Income) Loss from Affiliates | K22: =IFERROR(C22/$C$5*100,"") -> -0.075711228 | L22: =IFERROR(D22/$D$5*100,"") -> -0.082712197 | M22: =IFERROR(E22/$E$5*100,"") -> -0.16208305 | N22: =IFERROR(F22/$F$5*100,"") -> -0.42597682 | O22: =IFERROR(G22/$G$5*100,"") -> -0.096616377
A23: + Other Non-Op (Income) Loss | B23: 130.7 | C23: 207.6 | D23: -93.7 | E23: 2089.1 | F23: 508.4 | G23: 146 | J23: + Other Non-Op (Income) Loss | K23: =IFERROR(C23/$C$5*100,"") -> 0.30168236 | L23: =IFERROR(D23/$D$5*100,"") -> -0.12767929 | M23: =IFERROR(E23/$E$5*100,"") -> 1.99181 | N23: =IFERROR(F23/$F$5*100,"") -> 0.26670766 | O23: =IFERROR(G23/$G$5*100,"") -> 0.080882976
A24: Pretax Income (Loss), Adjusted | B24: 2120.4 | C24: 2825.9 | D24: 2924.3 | E24: 1486.3 | F24: 11185.8 | G24: 9309.1 | J24: Pretax Income (Loss), Adjusted | K24: =IFERROR(C24/$C$5*100,"") -> 4.1065712 | L24: =IFERROR(D24/$D$5*100,"") -> 3.9847657 | M24: =IFERROR(E24/$E$5*100,"") -> 1.4170826 | N24: =IFERROR(F24/$F$5*100,"") -> 5.868093 | O24: =IFERROR(G24/$G$5*100,"") -> 5.1571761
A25: - Abnormal Losses (Gains) | B25: -131.8 | C25: -194.9 | D25: -130.1 | E25: -104.5 | F25: 375.1 | G25: 355.7 | J25: - Abnormal Losses (Gains) | K25: =IFERROR(C25/$C$5*100,"") -> -0.28322684 | L25: =IFERROR(D25/$D$5*100,"") -> -0.17727935 | M25: =IFERROR(E25/$E$5*100,"") -> -0.099633406 | N25: =IFERROR(F25/$F$5*100,"") -> 0.19677821 | O25: =IFERROR(G25/$G$5*100,"") -> 0.19705531
A26: + Disposal of Assets | B26: -149.3 | C26: -127.1 | D26: 31.6 | E26: -90.6 | F26: 14.4 | G26: 3.2 | J26: + Disposal of Assets | K26: =IFERROR(C26/$C$5*100,"") -> -0.18470052 | L26: =IFERROR(D26/$D$5*100,"") -> 0.043059397 | M26: =IFERROR(E26/$E$5*100,"") -> -0.086380733 | N26: =IFERROR(F26/$F$5*100,"") -> 0.0075542688 | O26: =IFERROR(G26/$G$5*100,"") -> 0.0017727776
A27: + Asset Write-Down | B27: — | C27: — | D27: — | E27: — | F27: 555.8 | G27: 702.8 | J27: + Asset Write-Down | K27: =IFERROR(C27/$C$5*100,"") | L27: =IFERROR(D27/$D$5*100,"") | M27: =IFERROR(E27/$E$5*100,"") | N27: =IFERROR(F27/$F$5*100,"") -> 0.29157379 | O27: =IFERROR(G27/$G$5*100,"") -> 0.38934627
A28: + Impairment of Goodwill | B28: 68.6 | C28: — | D28: — | E28: — | F28: — | G28: — | J28: + Impairment of Goodwill | K28: =IFERROR(C28/$C$5*100,"") | L28: =IFERROR(D28/$D$5*100,"") | M28: =IFERROR(E28/$E$5*100,"") | N28: =IFERROR(F28/$F$5*100,"") | O28: =IFERROR(G28/$G$5*100,"")
A29: + Gain/Loss on Sale/Acquisition of Business | B29: — | C29: — | D29: -125.8 | E29: — | F29: -185.1 | G29: -278.7 | J29: + Gain/Loss on Sale/Acquisition of Business | K29: =IFERROR(C29/$C$5*100,"") | L29: =IFERROR(D29/$D$5*100,"") -> -0.17142001 | M29: =IFERROR(E29/$E$5*100,"") | N29: =IFERROR(F29/$F$5*100,"") -> -0.09710383 | O29: =IFERROR(G29/$G$5*100,"") -> -0.15439785
A30: + Sale of Investments | B30: -51.1 | C30: -67.8 | D30: -35.9 | E30: -13.9 | F30: -6.7 | G30: -50.2 | J30: + Sale of Investments | K30: =IFERROR(C30/$C$5*100,"") -> -0.098526319 | L30: =IFERROR(D30/$D$5*100,"") -> -0.048918746 | M30: =IFERROR(E30/$E$5*100,"") -> -0.013252673 | N30: =IFERROR(F30/$F$5*100,"") -> -0.0035148334 | O30: =IFERROR(G30/$G$5*100,"") -> -0.027810448
A31: + Unrealized Investments | B31: — | C31: — | D31: — | E31: — | F31: -3.3 | G31: -21.4 | J31: + Unrealized Investments | K31: =IFERROR(C31/$C$5*100,"") | L31: =IFERROR(D31/$D$5*100,"") | M31: =IFERROR(E31/$E$5*100,"") | N31: =IFERROR(F31/$F$5*100,"") -> -0.0017311866 | O31: =IFERROR(G31/$G$5*100,"") -> -0.01185545
A32: + Other Abnormal Items | B32: — | C32: — | D32: — | E32: — | F32: — | G32: — | J32: + Other Abnormal Items | K32: =IFERROR(C32/$C$5*100,"") | L32: =IFERROR(D32/$D$5*100,"") | M32: =IFERROR(E32/$E$5*100,"") | N32: =IFERROR(F32/$F$5*100,"") | O32: =IFERROR(G32/$G$5*100,"")
A33: Pretax Income (Loss), GAAP | B33: 2252.2 | C33: 3020.8 | D33: 3054.4 | E33: 1590.8 | F33: 10810.7 | G33: 8953.4 | J33: Pretax Income (Loss), GAAP | K33: =IFERROR(C33/$C$5*100,"") -> 4.389798 | L33: =IFERROR(D33/$D$5*100,"") -> 4.162045 | M33: =IFERROR(E33/$E$5*100,"") -> 1.516716 | N33: =IFERROR(F33/$F$5*100,"") -> 5.6713148 | O33: =IFERROR(G33/$G$5*100,"") -> 4.9601208
A34: - Income Tax Expense (Benefit) | B34: 512.6 | C34: 542.4 | D34: 711 | E34: 639.7 | F34: 2570.2 | G34: 2421.3 | J34: - Income Tax Expense (Benefit) | K34: =IFERROR(C34/$C$5*100,"") -> 0.78821056 | L34: =IFERROR(D34/$D$5*100,"") -> 0.96883644 | M34: =IFERROR(E34/$E$5*100,"") -> 0.609909 | N34: =IFERROR(F34/$F$5*100,"") -> 1.3483321 | O34: =IFERROR(G34/$G$5*100,"") -> 1.3413832
A35: + Current Income Tax | B35: 602.8 | C35: 925.3 | D35: 1345 | E35: 1267.7 | F35: 2803.3 | G35: 2508.2 | J35: + Current Income Tax | K35: =IFERROR(C35/$C$5*100,"") -> 1.3446372 | L35: =IFERROR(D35/$D$5*100,"") -> 1.8327497 | M35: =IFERROR(E35/$E$5*100,"") -> 1.2086629 | N35: =IFERROR(F35/$F$5*100,"") -> 1.4706168 | O35: =IFERROR(G35/$G$5*100,"") -> 1.3895252
A36: + Deferred Income Tax | B36: -90.2 | C36: -382.9 | D36: -634 | E36: -628 | F36: -233.1 | G36: -86.9 | J36: + Deferred Income Tax | K36: =IFERROR(C36/$C$5*100,"") -> -0.55642666 | L36: =IFERROR(D36/$D$5*100,"") -> -0.86391323 | M36: =IFERROR(E36/$E$5*100,"") -> -0.59875387 | N36: =IFERROR(F36/$F$5*100,"") -> -0.12228473 | O36: =IFERROR(G36/$G$5*100,"") -> -0.048141991
A37: + Tax Allowance/Credit | B37: — | C37: — | D37: — | E37: — | F37: — | G37: — | J37: + Tax Allowance/Credit | K37: =IFERROR(C37/$C$5*100,"") | L37: =IFERROR(D37/$D$5*100,"") | M37: =IFERROR(E37/$E$5*100,"") | N37: =IFERROR(F37/$F$5*100,"") | O37: =IFERROR(G37/$G$5*100,"")
A38: - (Income) Loss from Affiliates | B38: — | C38: — | D38: — | E38: — | F38: — | G38: — | J38: - (Income) Loss from Affiliates | K38: =IFERROR(C38/$C$5*100,"") | L38: =IFERROR(D38/$D$5*100,"") | M38: =IFERROR(E38/$E$5*100,"") | N38: =IFERROR(F38/$F$5*100,"") | O38: =IFERROR(G38/$G$5*100,"")
A39: Income (Loss) from Cont Ops | B39: 1739.6 | C39: 2478.4 | D39: 2343.4 | E39: 951.1 | F39: 8240.5 | G39: 6532.1 | J39: Income (Loss) from Cont Ops | K39: =IFERROR(C39/$C$5*100,"") -> 3.6015875 | L39: =IFERROR(D39/$D$5*100,"") -> 3.1932086 | M39: =IFERROR(E39/$E$5*100,"") -> 0.90680701 | N39: =IFERROR(F39/$F$5*100,"") -> 4.3229828 | O39: =IFERROR(G39/$G$5*100,"") -> 3.6187376
A40: - Net Extraordinary Losses (Gains) | B40: 0 | C40: 0 | D40: 0 | E40: 0 | F40: -1405.4 | G40: 0 | J40: - Net Extraordinary Losses (Gains) | K40: =IFERROR(C40/$C$5*100,"") -> 0 | L40: =IFERROR(D40/$D$5*100,"") -> 0 | M40: =IFERROR(E40/$E$5*100,"") -> 0 | N40: =IFERROR(F40/$F$5*100,"") -> -0.73727565 | O40: =IFERROR(G40/$G$5*100,"") -> 0
A41: + Discontinued Operations | B41: 0 | C41: 0 | D41: 0 | E41: 0 | F41: -1405.4 | G41: 0 | J41: + Discontinued Operations | K41: =IFERROR(C41/$C$5*100,"") -> 0 | L41: =IFERROR(D41/$D$5*100,"") -> 0 | M41: =IFERROR(E41/$E$5*100,"") -> 0 | N41: =IFERROR(F41/$F$5*100,"") -> -0.73727565 | O41: =IFERROR(G41/$G$5*100,"") -> 0
...

Sheet Ratio Analysis 
A1: Liquidity Ratios
C2: FY 2019 | D2: FY 2020 | E2: FY 2021 | F2: FY 2022 | G2: FY 2023
A3: Current ratio | B3: Allcargo | C3: =roundup('Horizontal Analysis - Allcargo'!C90/'Horizontal Analysis - Allcargo'!C124,3) -> 1.13 | D3: =roundup('Horizontal Analysis - Allcargo'!D90/'Horizontal Analysis - Allcargo'!D124,3) -> 1.063 | E3: =roundup('Horizontal Analysis - Allcargo'!E90/'Horizontal Analysis - Allcargo'!E124,3) -> 0.957 | F3: =roundup('Horizontal Analysis - Allcargo'!F90/'Horizontal Analysis - Allcargo'!F124,3) -> 1.137 | G3: =roundup('Horizontal Analysis - Allcargo'!G90/'Horizontal Analysis - Allcargo'!G124,3) -> 1.328
B4: BlueDart | C4: =ROUNDUP(('BS - BlueDart'!C37/'BS - BlueDart'!C70),3) -> 2.122 | D4: =ROUNDUP(('BS - BlueDart'!D37/'BS - BlueDart'!D70),3) -> 1.592 | E4: =ROUNDUP(('BS - BlueDart'!E37/'BS - BlueDart'!E70),3) -> 1.791 | F4: =ROUNDUP(('BS - BlueDart'!F37/'BS - BlueDart'!F70),3) -> 2.563 | G4: =ROUNDUP(('BS - BlueDart'!G37/'BS - BlueDart'!G70),3) -> 2.332
B5: Delhivery | C5: =ROUNDUP(('BS - Delhivery'!B17/'BS - Delhivery'!B43),3) -> 8.543 | D5: =ROUNDUP(('BS - Delhivery'!C17/'BS - Delhivery'!C43),3) -> 3.766 | E5: =ROUNDUP(('BS - Delhivery'!D17/'BS - Delhivery'!D43),3) -> 2.969 | F5: =ROUNDUP(('BS - Delhivery'!E17/'BS - Delhivery'!E43),3) -> 2.637 | G5: =ROUNDUP(('BS - Delhivery'!F17/'BS - Delhivery'!F43),3) -> 5.417
A6: Inferences: | B6: 1. The increase in current ratio from 2020 to 2023 for Allcargo logistics suggests an improvement in a company's short-term liquidity and financial health.
B7: 2. After Benchmarking with copmpetitors, the company isnt doing as well as Delhivery or BlueDart
B8: 3. A dip in the ratio from 2019 to 2020 could have been caused by COVID 19
C9: FY 2019 | D9: FY 2020 | E9: FY 2021 | F9: FY 2022 | G9: FY 2023
A10: Cash ratio | B10: Allcargo | C10: =roundup(('Horizontal Analysis - Allcargo'!C90-'Horizontal Analysis - Allcargo'!C78)/'Horizontal Analysis - Allcargo'!C124, 3) -> 1.124 | D10: =roundup(('Horizontal Analysis - Allcargo'!D90-'Horizontal Analysis - Allcargo'!D78)/'Horizontal Analysis - Allcargo'!D124, 3) -> 1.059 | E10: =roundup(('Horizontal Analysis - Allcargo'!E90-'Horizontal Analysis - Allcargo'!E78)/'Horizontal Analysis - Allcargo'!E124, 3) -> 0.955 | F10: =roundup(('Horizontal Analysis - Allcargo'!F90-'Horizontal Analysis - Allcargo'!F78)/'Horizontal Analysis - Allcargo'!F124, 3) -> 1.135 | G10: =roundup(('Horizontal Analysis - Allcargo'!G90-'Horizontal Analysis - Allcargo'!G78)/'Horizontal Analysis - Allcargo'!G124, 3) -> 1.327
B11: BlueDart | C11: =ROUNDUP(('BS - BlueDart'!C20-'BS - BlueDart'!C10)/'BS - BlueDart'!C55, 3) -> 1.065 | D11: =ROUNDUP(('BS - BlueDart'!D20-'BS - BlueDart'!D10)/'BS - BlueDart'!D55, 3) -> 0.736 | E11: =ROUNDUP(('BS - BlueDart'!E20-'BS - BlueDart'!E10)/'BS - BlueDart'!E55, 3) -> 0.813 | F11: =ROUNDUP(('BS - BlueDart'!F20-'BS - BlueDart'!F10)/'BS - BlueDart'!F55, 3) -> 0.819 | G11: =ROUNDUP(('BS - BlueDart'!G20-'BS - BlueDart'!G10)/'BS - BlueDart'!G55, 3) -> 0.915
B12: Delhivery | C12: =ROUNDUP(('BS - Delhivery'!B17-'BS - Delhivery'!B10)/'BS - Delhivery'!B43, 3) -> 8.484 | D12: =ROUNDUP(('BS - Delhivery'!C17-'BS - Delhivery'!C10)/'BS - Delhivery'!C43, 3) -> 3.74 | E12: =ROUNDUP(('BS - Delhivery'!D17-'BS - Delhivery'!D10)/'BS - Delhivery'!D43, 3) -> 2.941 | F12: =ROUNDUP(('BS - Delhivery'!E17-'BS - Delhivery'!E10)/'BS - Delhivery'!E43, 3) -> 2.62 | G12: =ROUNDUP(('BS - Delhivery'!F17-'BS - Delhivery'!F10)/'BS - Delhivery'!F43, 3) -> 5.402
A13: Inferences: | B13: 1. The dip in the ratio for Allcargo logistic scould have been caused by COVID 19 pandemic
B14: 2. The increase from 2020 to 2023 suggests an improvement in a company's liquidity, specifically in terms of its ability to cover short-term liabilities with cash and cash equivalents
B15: 3. The order of liquidity can be Delhivery>Allcargo>BlueDart
A16: Leverage Financial Ratios
C17: FY 2019 | D17: FY 2020 | E17: FY 2021 | F17: FY 2022 | G17: FY 2023
A18: Debt to assets ratio | B18: Allcargo | C18: =roundup(('Horizontal Analysis - Allcargo'!C115+'Horizontal Analysis - Allcargo'!C125)/'Horizontal Analysis - Allcargo'!C107,3) -> 0.127 | D18: =roundup(('Horizontal Analysis - Allcargo'!D115+'Horizontal Analysis - Allcargo'!D125)/'Horizontal Analysis - Allcargo'!D107,3) -> 0.272 | E18: =roundup(('Horizontal Analysis - Allcargo'!E115+'Horizontal Analysis - Allcargo'!E125)/'Horizontal Analysis - Allcargo'!E107,3) -> 0.239 | F18: =roundup(('Horizontal Analysis - Allcargo'!F115+'Horizontal Analysis - Allcargo'!F125)/'Horizontal Analysis - Allcargo'!F107,3) -> 0.213 | G18: =roundup(('Horizontal Analysis - Allcargo'!G115+'Horizontal Analysis - Allcargo'!G125)/'Horizontal Analysis - Allcargo'!G107,3) -> 0.161
B19: BlueDart | C19: =ROUNDUP(('BS - BlueDart'!C46+'BS - BlueDart'!C56)/'BS - BlueDart'!C38,3) -> 0.274 | D19: =ROUNDUP(('BS - BlueDart'!D46+'BS - BlueDart'!D56)/'BS - BlueDart'!D38,3) -> 0.508 | E19: =ROUNDUP(('BS - BlueDart'!E46+'BS - BlueDart'!E56)/'BS - BlueDart'!E38,3) -> 0.405 | F19: =ROUNDUP(('BS - BlueDart'!F46+'BS - BlueDart'!F56)/'BS - BlueDart'!F38,3) -> 0.377 | G19: =ROUNDUP(('BS - BlueDart'!G46+'BS - BlueDart'!G56)/'BS - BlueDart'!G38,3) -> 0.348
B20: Delhivery | C20: =ROUNDUP(('BS - Delhivery'!B37+'BS - Delhivery'!B44)/'BS - Delhivery'!B31,3) -> 0.102 | D20: =ROUNDUP(('BS - Delhivery'!C37+'BS - Delhivery'!C44)/'BS - Delhivery'!C31,3) -> 0.174 | E20: =ROUNDUP(('BS - Delhivery'!D37+'BS - Delhivery'!D44)/'BS - Delhivery'!D31,3) -> 0.243 | F20: =ROUNDUP(('BS - Delhivery'!E37+'BS - Delhivery'!E44)/'BS - Delhivery'!E31,3) -> 0.134 | G20: =ROUNDUP(('BS - Delhivery'!F37+'BS - Delhivery'!F44)/'BS - Delhivery'!F31,3) -> 0.083
A21: Inferences: | B21: 1. A decrease in the debt-to-assets ratio for Allcargo Logistics typically indicates a positive financial development for a company
B22: 2. Delhivery seems to outperform Allcargo and BlueDart having the least of Debt to asset ratio across last 5 years
C23: FY 2019 | D23: FY 2020 | E23: FY 2021 | F23: FY 2022 | G23: FY 2023
A24: Debt to equity ratio | B24: Allcargo | C24: =roundup(('Horizontal Analysis - Allcargo'!C115+'Horizontal Analysis - Allcargo'!C125)/'Horizontal Analysis - Allcargo'!C148,3) -> 0.247 | D24: =roundup(('Horizontal Analysis - Allcargo'!D115+'Horizontal Analysis - Allcargo'!D125)/'Horizontal Analysis - Allcargo'!D148,3) -> 0.664 | E24: =roundup(('Horizontal Analysis - Allcargo'!E115+'Horizontal Analysis - Allcargo'!E125)/'Horizontal Analysis - Allcargo'!E148,3) -> 0.68 | F24: =roundup(('Horizontal Analysis - Allcargo'!F115+'Horizontal Analysis - Allcargo'!F125)/'Horizontal Analysis - Allcargo'!F148,3) -> 0.585 | G24: =roundup(('Horizontal Analysis - Allcargo'!G115+'Horizontal Analysis - Allcargo'!G125)/'Horizontal Analysis - Allcargo'!G148,3) -> 0.379
B25: BlueDart | C25: =ROUNDUP(('BS - BlueDart'!C46+'BS - BlueDart'!C56)/'BS - BlueDart'!C81,3) -> 0.859 | D25: =ROUNDUP(('BS - BlueDart'!D46+'BS - BlueDart'!D56)/'BS - BlueDart'!D81,3) -> 2.732 | E25: =ROUNDUP(('BS - BlueDart'!E46+'BS - BlueDart'!E56)/'BS - BlueDart'!E81,3) -> 1.981 | F25: =ROUNDUP(('BS - BlueDart'!F46+'BS - BlueDart'!F56)/'BS - BlueDart'!F81,3) -> 1.223 | G25: =ROUNDUP(('BS - BlueDart'!G46+'BS - BlueDart'!G56)/'BS - BlueDart'!G81,3) -> 0.95
B26: Delhivery | C26: =ROUNDUP(('BS - Delhivery'!B37+'BS - Delhivery'!B44)/'BS - Delhivery'!B61,3) -> 0.122 | D26: =ROUNDUP(('BS - Delhivery'!C37+'BS - Delhivery'!C44)/'BS - Delhivery'!C61,3) -> 0.239 | E26: =ROUNDUP(('BS - Delhivery'!D37+'BS - Delhivery'!D44)/'BS - Delhivery'!D61,3) -> 0.394 | F26: =ROUNDUP(('BS - Delhivery'!E37+'BS - Delhivery'!E44)/'BS - Delhivery'!E61,3) -> 0.185 | G26: =ROUNDUP(('BS - Delhivery'!F37+'BS - Delhivery'!F44)/'BS - Delhivery'!F61,3) -> 0.101
A27: Inferences: | B27: 1 An almost stable debt to equity ratio suggests that Allcargo has had a stable in the journey past 5 years
B28: 2. A suddent increase in the debt to equity ratio during the FY 2020 could be caused by the heavy debt intake during the COVID19 pandemic due to shutting down of logistics business in some regions
A29: Efficiency Ratios
C30: FY 2019 | D30: FY 2020 | E30: FY 2021 | F30: FY 2022 | G30: FY 2023
A31: Asset turnover ratio | B31: Allcargo | C31: =roundup('Horizontal Analysis - Allcargo'!C6*2/('Horizontal Analysis - Allcargo'!B90+'Horizontal Analysis - Allcargo'!C90), 3) -> 4.464 | D31: =roundup('Horizontal Analysis - Allcargo'!D6*2/('Horizontal Analysis - Allcargo'!C90+'Horizontal Analysis - Allcargo'!D90), 3) -> 3.707 | E31: =roundup('Horizontal Analysis - Allcargo'!E6*2/('Horizontal Analysis - Allcargo'!D90+'Horizontal Analysis - Allcargo'!E90), 3) -> 3.615 | F31: =roundup('Horizontal Analysis - Allcargo'!F6*2/('Horizontal Analysis - Allcargo'!E90+'Horizontal Analysis - Allcargo'!F90), 3) -> 4.335 | G31: =roundup('Horizontal Analysis - Allcargo'!G6*2/('Horizontal Analysis - Allcargo'!F90+'Horizontal Analysis - Allcargo'!G90), 3) -> 3.715
B32: BlueDart | C32: =roundup(('IS - BlueDart'!C4*2/('BS - BlueDart'!B38 +'BS - BlueDart'!C38)),3) -> 1.916 | D32: =roundup(('IS - BlueDart'!D4*2/('BS - BlueDart'!C38 +'BS - BlueDart'!D38)),3) -> 1.427 | E32: =roundup(('IS - BlueDart'!E4*2/('BS - BlueDart'!D38 +'BS - BlueDart'!E38)),3) -> 1.188 | F32: =roundup(('IS - BlueDart'!F4*2/('BS - BlueDart'!E38 +'BS - BlueDart'!F38)),3) -> 1.541 | G32: =roundup(('IS - BlueDart'!G4*2/('BS - BlueDart'!F38 +'BS - BlueDart'!G38)),3) -> 1.71
B33: Delhivery | D33: =roundup(('IS - Delhivery'!C4*2/('BS - Delhivery'!B31+'BS - Delhivery'!C31)),3) -> 0.661 | E33: =roundup(('IS - Delhivery'!D4*2/('BS - Delhivery'!C31+'BS - Delhivery'!D31)),3) -> 0.815 | F33: =roundup(('IS - Delhivery'!E4*2/('BS - Delhivery'!D31+'BS - Delhivery'!E31)),3) -> 1.072 | G33: =roundup(('IS - Delhivery'!F4*2/('BS - Delhivery'!E31+'BS - Delhivery'!F31)),3) -> 0.744
A34: Inferences: | B34: 1. A slight drop in the asset turnover ratio for Allcargo Logistics across past 5 years suggests a decline in a company's efficiency in generating sales from its assets. It may indicate that the company is not effectively utilizing its assets to generate revenue, which can be a concern for operational efficiency and profitability.
C35: FY 2019 | D35: FY 2020 | E35: FY 2021 | F35: FY 2022 | G35: FY 2023
A36: Inventory turnover ratio | B36: Allcargo | C36: ='Horizontal Analysis - Allcargo'!C6*2/('Horizontal Analysis - Allcargo'!B78+'Horizontal Analysis - Allcargo'!C78) -> 745.54821 | D36: ='Horizontal Analysis - Allcargo'!D6*2/('Horizontal Analysis - Allcargo'!C78+'Horizontal Analysis - Allcargo'!D78) -> 882.05529 | E36: ='Horizontal Analysis - Allcargo'!E6*2/('Horizontal Analysis - Allcargo'!D78+'Horizontal Analysis - Allcargo'!E78) -> 1200.7384 | F36: ='Horizontal Analysis - Allcargo'!F6*2/('Horizontal Analysis - Allcargo'!E78+'Horizontal Analysis - Allcargo'!F78) -> 2472.3826 | G36: ='Horizontal Analysis - Allcargo'!G6*2/('Horizontal Analysis - Allcargo'!F78+'Horizontal Analysis - Allcargo'!G78) -> 4429.6368
B37: BlueDart | C37: =ROUNDUP('IS - BlueDart'!C4*2/('BS - BlueDart'!B10+'BS - BlueDart'!C10), 3) -> 134.111 | D37: =ROUNDUP('IS - BlueDart'!D4*2/('BS - BlueDart'!C10+'BS - BlueDart'!D10), 3) -> 119.817 | E37: =ROUNDUP('IS - BlueDart'!E4*2/('BS - BlueDart'!D10+'BS - BlueDart'!E10), 3) -> 111.899 | F37: =ROUNDUP('IS - BlueDart'!F4*2/('BS - BlueDart'!E10+'BS - BlueDart'!F10), 3) -> 132.11 | G37: =ROUNDUP('IS - BlueDart'!G4*2/('BS - BlueDart'!F10+'BS - BlueDart'!G10), 3) -> 139.151
B38: Delhivery | C38: - | D38: =ROUNDUP('IS - Delhivery'!C4/('BS - Delhivery'!B10+'BS - Delhivery'!C10), 3) -> 68.716 | E38: =ROUNDUP('IS - Delhivery'!D4/('BS - Delhivery'!C10+'BS - Delhivery'!D10), 3) -> 83.293 | F38: =ROUNDUP('IS - Delhivery'!E4/('BS - Delhivery'!D10+'BS - Delhivery'!E10), 3) -> 134.279 | G38: =ROUNDUP('IS - Delhivery'!F4/('BS - Delhivery'!E10+'BS - Delhivery'!F10), 3) -> 161.778
A39: Inferences: | B39: 1. A high inventory turnove ratio for Allcargo logistics suggests that products are selling in a timely manner, and that sales are good in a given period. However, an inventory ratio that is too high could mean that it need to replenish inventory constantly, which could lead to stockouts.
C40: FY 2019 | D40: FY 2020 | E40: FY 2021 | F40: FY 2022 | G40: FY 2023
...

Sheet Dupont Analysis
A1: ROE = (Net Income/Sales)x(sales/Total Assets)x(Total Assets/Equity)
A3: ROE = (Profitability)x(Efficiency)x(Equity Multiplier)
A5: Dupont Analysis for FY 2023
B6: Profitability | C6: Efficiency | D6: Equity Multiplier | F6: ROE
A7: Allcargo logistics | B7: =roundup('Horizontal Analysis - Allcargo'!C50/'Horizontal Analysis - Allcargo'!C6,3) -> 0.034 | C7: ='Ratio Analysis '!G31 -> 3.715 | D7: =roundup('Horizontal Analysis - Allcargo'!C107/'Horizontal Analysis - Allcargo'!C148,3) -> 1.94 | F7: =B7*C7*D7*100 -> 24.50414
A8: BlueDart | B8: =roundup('IS - BlueDart'!C44/'IS - BlueDart'!C4,3) -> 0.029 | C8: ='Ratio Analysis '!G32 -> 1.71 | D8: =roundup('BS - BlueDart'!C38/'BS - BlueDart'!C81,3) -> 3.136 | F8: =B8*C8*D8*100 -> 15.551424
A9: Delhivery | B9: =roundup('IS - Delhivery'!C35/'IS - Delhivery'!C4,3) -> -0.097 | C9: ='Ratio Analysis '!G33 -> 0.744 | D9: =roundup('BS - Delhivery'!B31/'BS - Delhivery'!B61,3) -> 1.199 | F9: =B9*C9*D9*100 -> -8.6529432
A11: Inferences:
B12: 1. The ROE calculated from the dupon analysis is 24.50 for Allcargo which is almost close to calculated by raw calculation from financial statements i.e. 21.017
B13: 2. This shows the accuracy of the method

Sheet IS - BlueDart
A1: In Millions of INR except Per Share | B1: FY 2018 | C1: FY 2019 | D1: FY 2020 | E1: FY 2021 | F1: FY 2022 | G1: FY 2023
A2: 12 Months Ending | B2: 03/31/2018 | C2: 03/31/2019 | D2: 03/31/2020 | E2: 03/31/2021 | F2: 03/31/2022 | G2: 03/31/2023
A3: Revenue | B3: 27992.4 | C3: 31744 | D3: 31751.3 | E3: 32881.3 | F3: 44104.9 | G3: 51722.2
A4: + Sales & Services Revenue | B4: 27992.4 | C4: 31744 | D4: 31751.3 | E4: 32881.3 | F4: 44104.9 | G4: 51722.2
A5: Gross Profit | B5: — | C5: — | D5: — | E5: — | F5: — | G5: —
A6: + Other Operating Income | B6: 74.6 | C6: 73.9 | D6: 55.3 | E6: 127.3 | F6: 307.9 | G6: 0
A7: - Operating Expenses | B7: 25617.5 | C7: 30161.1 | D7: 30478.5 | E7: 30318.4 | F7: 38046.7 | G7: 46290.9
A8: + Selling & Marketing | B8: 21.3 | C8: 16 | D8: 20.2 | E8: 68.3 | F8: 93.2 | G8: 91.7
A9: + Research & Development | B9: 0 | C9: 0 | D9: 0 | E9: — | F9: — | G9: 0
A10: + Depreciation & Amortization | B10: 1144.5 | C10: 1278.9 | D10: 3473.3 | E10: 4300 | F10: 3953.7 | G10: 3944.8
A11: + Prov For Doubtful Accts | B11: — | C11: — | D11: — | E11: — | F11: — | G11: 34.8
A12: + Other Operating Expense | B12: 24451.7 | C12: 28866.2 | D12: 26985 | E12: 25950.1 | F12: 33999.8 | G12: 42219.6
A13: Operating Income (Loss) | B13: 2449.5 | C13: 1656.8 | D13: 1328.1 | E13: 2690.2 | F13: 6366.1 | G13: 5431.3
A14: - Non-Operating (Income) Loss | B14: 272.9 | C14: 308.1 | D14: 1715 | E14: 1292.3 | F14: 1294.9 | G14: 519.2
A15: + Interest Expense, Net | B15: 309.1 | C15: 350.8 | D15: 1104.9 | E15: 1033.8 | F15: 798.9 | G15: 643.5
A16: + Interest Expense | B16: 405 | C16: 426.6 | D16: 1173.8 | E16: 1109.5 | F16: 869.7 | G16: 668.5
A17: - Interest Income | B17: 95.9 | C17: 75.8 | D17: 68.9 | E17: 75.7 | F17: 70.8 | G17: 25
A18: + Other Investment (Inc) Loss | B18: -35.4 | C18: -33.8 | D18: -30.5 | E18: 0 | F18: 0 | G18: —
A19: + Foreign Exch (Gain) Loss | B19: -0.8 | C19: -8.9 | D19: -0.5 | E19: 0 | F19: 0 | G19: 0
A20: + (Income) Loss from Affiliates | B20: — | C20: — | D20: — | E20: — | F20: 0 | G20: —
A21: + Other Non-Op (Income) Loss | B21: 0 | C21: 0 | D21: 641.1 | E21: 258.5 | F21: 496 | G21: -124.3
A22: Pretax Income (Loss), Adjusted | B22: 2176.6 | C22: 1348.7 | D22: -386.9 | E22: 1397.9 | F22: 5071.2 | G22: 4912.1
A23: - Abnormal Losses (Gains) | B23: 6.6 | C23: 7.3 | D23: 4.3 | E23: 0 | F23: -51.7 | G23: -169.9
A24: + Disposal of Assets | B24: 6.6 | C24: 7.3 | D24: 4.3 | E24: — | F24: 1.1 | G24: -0.6
A25: + Asset Write-Down | B25: — | C25: — | D25: — | E25: — | F25: 11.8 | G25: —
A26: + Sale of Investments | B26: — | C26: — | D26: — | E26: — | F26: -64.6 | G26: -169.3
A27: Pretax Income (Loss), GAAP | B27: 2170 | C27: 1341.4 | D27: -391.2 | E27: 1397.9 | F27: 5122.9 | G27: 5082
A28: - Income Tax Expense (Benefit) | B28: 722.9 | C28: 443.8 | D28: 27.4 | E28: 379.8 | F28: 1300.8 | G28: 1376.7
A29: + Current Income Tax | B29: 796.5 | C29: 527.3 | D29: 128.3 | E29: 540.2 | F29: 1373.5 | G29: 1471.3
A30: + Deferred Income Tax | B30: -73.6 | C30: -83.5 | D30: -100.9 | E30: -160.4 | F30: -72.7 | G30: -94.6
A31: + Tax Allowance/Credit | B31: — | C31: — | D31: — | E31: — | F31: — | G31: —
A32: - (Income) Loss from Affiliates | B32: — | C32: — | D32: — | E32: 0 | F32: 0 | G32: —
A33: Income (Loss) from Cont Ops | B33: 1447.1 | C33: 897.6 | D33: -418.6 | E33: 1018.1 | F33: 3822.1 | G33: 3705.3
A34: - Net Extraordinary Losses (Gains) | B34: 0 | C34: 0 | D34: 0 | E34: 0 | F34: 0 | G34: 0
A35: + Discontinued Operations | B35: 0 | C35: 0 | D35: 0 | E35: 0 | F35: 0 | G35: 0
A36: + XO & Accounting Changes | B36: 0 | C36: 0 | D36: 0 | E36: 0 | F36: 0 | G36: 0
A37: Income (Loss) Incl. MI | B37: 1447.1 | C37: 897.6 | D37: -418.6 | E37: 1018.1 | F37: 3822.1 | G37: 3705.3
A38: - Minority Interest | B38: 0 | C38: 0 | D38: 0 | E38: 0 | F38: 0 | G38: 0
A39: Net Income, GAAP | B39: 1447.1 | C39: 897.6 | D39: -418.6 | E39: 1018.1 | F39: 3822.1 | G39: 3705.3
A40: - Preferred Dividends | B40: 0 | C40: 0 | D40: 0 | E40: 0 | F40: 0 | G40: 0
...

Sheet BS - BlueDart
A1: In Millions of INR except Per Share | B1: FY 2018 | C1: FY 2019 | D1: FY 2020 | E1: FY 2021 | F1: FY 2022 | G1: FY 2023
A2: 12 Months Ending | B2: 03/31/2018 | C2: 03/31/2019 | D2: 03/31/2020 | E2: 03/31/2021 | F2: 03/31/2022 | G2: 03/31/2023
A3: Total Assets
A4: + Cash, Cash Equivalents & STI | B4: 2278.7 | C4: 2687.1 | D4: 1000 | E4: 4605.9 | F4: 3917.2 | G4: 2664.1
A5: + Cash & Cash Equivalents | B5: 2278.7 | C5: 2687.1 | D5: 1000 | E5: 3105.2 | F5: 1843.3 | G5: 955.2
A6: + ST Investments | B6: 0 | C6: 0 | D6: 0 | E6: 1500.7 | F6: 2073.9 | G6: 1708.9
A7: + Accounts & Notes Receiv | B7: 4222.5 | C7: 4910.2 | D7: 5282.3 | E7: 5179.2 | F7: 5800.1 | G7: 6366.6
A8: + Accounts Receivable, Net | B8: 4222.5 | C8: 4910.2 | D8: 5282.3 | E8: 5179.2 | F8: 5800.1 | G8: 6366.6
A9: + Notes Receivable, Net | B9: 0 | C9: 0 | D9: 0 | E9: 0 | F9: 0 | G9: 0
A10: + Inventories | B10: 213.3 | C10: 260.1 | D10: 269.9 | E10: 317.8 | F10: 349.9 | G10: 393.5
A11: + Raw Materials | B11: 44.8 | C11: 58.9 | D11: 37.3 | E11: 58.2 | F11: 70.1 | G11: 78.4
A12: + Work In Process | B12: 0 | C12: 0 | D12: 0 | E12: 0 | F12: 0 | G12: 0
A13: + Finished Goods | B13: 0 | C13: 0 | D13: 0 | E13: 0 | F13: 0 | G13: 0
A14: + Other Inventory | B14: 168.5 | C14: 201.2 | D14: 232.6 | E14: 259.6 | F14: 279.8 | G14: 315.1
A15: + Other ST Assets | B15: 683.6 | C15: 774.2 | D15: 660.9 | E15: 700.9 | F15: 696 | G15: 1179.3
... A17: + Derivative & Hedging Assets | B17: 0 | C17: 0 | D17: 0 | E17: 0 | F17: 0 | G17: 0
A18: + Assets Held-for-Sale | B18: — | C18: — | D18: — | E18: — | F18: — | G18: —
A19: + Misc ST Assets | B19: 473 | C19: 470.4 | D19: 493.5 | E19: 504.5 | F19: 512.7 | G19: 756.1
A20: Total Current Assets | B20: 7398.1 | C20: 8631.6 | D20: 7213.1 | E20: 10803.8 | F20: 10763.2 | G20: 10603.5
A21: + Property, Plant & Equip, Net | B21: 5241.6 | C21: 6411.6 | D21: 15840.5 | E21: 15111.6 | F21: 14247 | G21: 18029.7
A22: + Property, Plant & Equip | B22: 7549.3 | C22: 9457.2 | D22: 20091.1 | E22: 20661.9 | F22: 25656.3 | G22: 32033.6
A23: - Accumulated Depreciation | B23: 2307.7 | C23: 3045.6 | D23: 4250.6 | E23: 5550.3 | F23: 11409.3 | G23: 14003.9
A24: + LT Investments & Receivables | B24: 0 | C24: 0 | D24: 0 | E24: 0 | F24: 0 | G24: 0
A25: + LT Investments | B25: 0 | C25: 0 | D25: 0 | E25: — | F25: 0 | G25: 0
A26: + LT Marketable Securities | B26: — | C26: — | D26: — | E26: — | F26: — | G26: 0
A27: + LT Receivables | B27: — | C27: — | D27: — | E27: 0 | F27: — | G27: —
A28: + Other LT Assets | B28: 2385.8 | C28: 3069.4 | D28: 3354.3 | E28: 3058.9 | F28: 3277.4 | G28: 3597.2
A29: + Total Intangible Assets | B29: 933.6 | C29: 1038.6 | D29: 989.6 | E29: 787 | F29: 813 | G29: 729.7
A30: + Goodwill | B30: 0 | C30: 0 | D30: 0 | E30: 0 | F30: 0 | G30: 0
A31: + Other Intangible Assets | B31: 933.6 | C31: 1038.6 | D31: 989.6 | E31: 787 | F31: 813 | G31: 729.7
A32: + Prepaid Expense | B32: 179.1 | C32: 122.3 | D32: 30.2 | E32: 60.3 | F32: 51.2 | G32: 114.1
A33: + Deferred Tax Assets | B33: 386.5 | C33: 513.2 | D33: 645.1 | E33: 807.8 | F33: 905.6 | G33: 1023.8
A34: + Derivative & Hedging Assets | B34: 0 | C34: 0 | D34: 0 | E34: 0 | F34: 0 | G34: 0
A35: + Investments in Affiliates | B35: — | C35: — | D35: — | E35: 0 | F35: 0 | G35: —
A36: + Misc LT Assets | B36: 886.6 | C36: 1395.3 | D36: 1689.4 | E36: 1403.8 | F36: 1507.6 | G36: 1729.6
A37: Total Noncurrent Assets | B37: 7627.4 | C37: 9481 | D37: 19194.8 | E37: 18170.5 | F37: 17524.4 | G37: 21626.9
A38: Total Assets | B38: 15025.5 | C38: 18112.6 | D38: 26407.9 | E38: 28974.3 | F38: 28287.6 | G38: 32230.4
A40: Liabilities & Shareholders' Equity
A41: + Payables & Accruals | B41: 5028.1 | C41: 6038.5 | D41: 6179.9 | E41: 7159.5 | F41: 8158.4 | G41: 7180.6
A42: + Accounts Payable | B42: 2759 | C42: 4342.5 | D42: 4010.3 | E42: 5094.1 | F42: 5798.7 | G42: 5851
...

Sheet IS - Delhivery
A1: In Millions of INR except Per Share | B1: FY 2019 | C1: FY 2020 | D1: FY 2021 | E1: FY 2022 | F1: FY 2023
A2: 12 Months Ending | B2: 03/31/2019 | C2: 03/31/2020 | D2: 03/31/2021 | E2: 03/31/2022 | F2: 03/31/2023
A3: Revenue | B3: 16538.97 | C3: 27805.75 | D3: 36465.27 | E3: 68822.86 | F3: 72253.01
A4: + Sales & Services Revenue | B4: 16538.97 | C4: 27805.75 | D4: 36465.27 | E4: 68822.86 | F4: 72253.01
A5: Gross Profit | B5: — | C5: — | D5: — | E5: — | F5: —
A6: - Operating Expenses | B6: 34423.65 | C6: 32082.13 | D6: 41240.77 | E6: 79847.18 | F6: 85220.35
A7: + Depreciation & Amortization | B7: 1700.05 | C7: 2555.91 | D7: 3546.2 | E7: 6107.47 | F7: 8311.44
A8: + Other Operating Expense | B8: 32723.6 | C8: 29526.22 | D8: 37694.57 | E8: 73739.71 | F8: 76908.91
A9: Operating Income (Loss) | B9: -17884.68 | C9: -4276.38 | D9: -4775.5 | E9: -11024.32 | F9: -12967.34
A10: - Non-Operating (Income) Loss | B10: -51.64 | C10: -1588.36 | D10: -618.07 | E10: -533.85 | F10: -2296.92
A11: + Interest Expense, Net | B11: — | C11: 492.18 | D11: 886.27 | E11: — | F11: —
A12: + Interest Expense | B12: 358.13 | C12: 492.18 | D12: 886.27 | E12: — | F12: —
A13: - Interest Income | B13: — | C13: 0 | D13: 0 | E13: — | F13: —
A14: + Foreign Exch (Gain) Loss | B14: 0 | C14: 0 | D14: 0 | E14: 0 | F14: 0
A15: + (Income) Loss from Affiliates | B15: — | C15: — | D15: — | E15: 32.27 | F15: -135.74
A16: + Other Non-Op (Income) Loss | B16: -409.77 | C16: -2080.54 | D16: -1504.34 | E16: -566.12 | F16: -2161.18
A17: Pretax Income (Loss), Adjusted | B17: -17833.04 | C17: -2688.02 | D17: -4157.43 | E17: -10490.47 | F17: -10670.42
A18: - Abnormal Losses (Gains) | B18: 0 | C18: 0 | D18: 0 | E18: -197.17 | F18: -139.82
A19: + Disposal of Assets | B19: — | C19: — | D19: — | E19: -0.08 | F19: —
A20: + Sale of Investments | B20: — | C20: — | D20: — | E20: -197.09 | F20: -139.82
A21: Pretax Income (Loss), GAAP | B21: -17833.04 | C21: -2688.02 | D21: -4157.43 | E21: -10293.3 | F21: -10530.6
A22: - Income Tax Expense (Benefit) | B22: 0 | C22: 1.24 | D22: 0 | E22: -183.3 | F22: -452.81
A23: + Current Income Tax | B23: 0 | C23: 1.24 | D23: 0 | E23: 100.72 | F23: 107.38
A24: + Deferred Income Tax | B24: 0 | C24: 0 | D24: 0 | E24: -284.02 | F24: -560.19
A25: Income (Loss) from Cont Ops | B25: -17833.04 | C25: -2689.26 | D25: -4157.43 | E25: -10110 | F25: -10077.79
A26: - Net Extraordinary Losses (Gains) | B26: 0 | C26: 0 | D26: 0 | E26: 0 | F26: 0
A27: + Discontinued Operations | B27: 0 | C27: 0 | D27: 0 | E27: 0 | F27: 0
A28: + XO & Accounting Changes | B28: 0 | C28: 0 | D28: 0 | E28: 0 | F28: 0
A29: Income (Loss) Incl. MI | B29: -17833.04 | C29: -2689.26 | D29: -4157.43 | E29: -10110 | F29: -10077.79
A30: Net Income, GAAP | B30: -17833.04 | C30: -2689.26 | D30: -4157.43 | E30: -10110 | F30: -10077.79
A31: - Preferred Dividends | B31: — | C31: — | D31: — | E31: 0 | F31: 0
A32: - Other Adjustments | B32: — | C32: 0 | D32: 0 | E32: 0 | F32: 0
A33: Net Income Avail to Common, GAAP | B33: -17833.04 | C33: -2689.26 | D33: -4157.43 | E33: -10110 | F33: -10077.79
A35: Net Income Avail to Common, Adj | B35: -17833.04 | C35: -2689.26 | D35: -4157.43 | E35: -10248.019 | F35: -10175.664
A36: Net Abnormal Losses (Gains) | B36: 0 | C36: 0 | D36: 0 | E36: -138.019 | F36: -97.874
A37: Net Extraordinary Losses (Gains) | B37: 0 | C37: 0 | D37: 0 | E37: 0 | F37: 0
A39: Basic Weighted Avg Shares | B39: — | C39: — | D39: — | E39: 642.11 | F39: 715.16
A40: Basic EPS, GAAP | B40: — | C40: — | D40: -8.05 | E40: -15.745 | F40: -14.09
A41: Basic EPS from Cont Ops, GAAP | B41: — | C41: — | D41: -8.05 | E41: -15.745 | F41: -14.09
A42: Basic EPS from Cont Ops, Adjusted | B42: — | C42: — | D42: -8.05 | E42: -15.9599 | F42: -14.2285
...

Sheet BS - Delhivery
A1: In Millions of INR except Per Share | B1: FY 2019 | C1: FY 2020 | D1: FY 2021 | E1: FY 2022 | F1: FY 2023
A2: 12 Months Ending | B2: 03/31/2019 | C2: 03/31/2020 | D2: 03/31/2021 | E2: 03/31/2022 | F2: 03/31/2023
A3: Total Assets
A4: + Cash, Cash Equivalents & STI | B4: 27938.59 | C4: 12191.41 | D4: 9850.05 | E4: 16902.33 | F4: 21271.72
A5: + Cash & Cash Equivalents | B5: 16634.32 | C5: 4087 | D5: 2774.41 | E5: 2290 | F5: 6454.52
A6: + ST Investments | B6: 11304.27 | C6: 8104.41 | D6: 7075.64 | E6: 14612.33 | F6: 14817.2
A7: + Accounts & Notes Receiv | B7: 2146.5 | C7: 6013.31 | D7: 5945.82 | E7: 9902.5 | F7: 9436.37
A8: + Accounts Receivable, Net | B8: — | C8: — | D8: — | E8: 9902.5 | F8: 9436.37
A9: + Notes Receivable, Net | B9: — | C9: — | D9: — | E9: 0 | F9: 0
A10: + Inventories | B10: 226.33 | C10: 178.32 | D10: 259.48 | E10: 253.06 | F10: 193.56
A11: + Raw Materials | B11: — | C11: 0 | D11: — | E11: — | F11: —
A12: + Work In Process | B12: — | C12: 0 | D12: — | E12: — | F12: —
A13: + Finished Goods | B13: — | C13: 178.32 | D13: 259.48 | E13: — | F13: —
A14: + Other Inventory | B14: — | C14: 0 | D14: — | E14: — | F14: —
A15: + Other ST Assets | B15: 2384.49 | C15: 7344.54 | D15: 12249.63 | E15: 12541.87 | F15: 38486.93
A16: + Misc ST Assets | B16: 2384.49 | C16: 7344.54 | D16: 12249.63 | E16: 12541.87 | F16: 38486.93
A17: Total Current Assets | B17: 32695.91 | C17: 25727.58 | D17: 28304.98 | E17: 39599.76 | F17: 69388.58
A18: + Property, Plant & Equip, Net | B18: 4594.04 | C18: 7407.27 | D18: 10975.3 | E18: 13750.02 | F18: 14833.43
A19: + Property, Plant & Equip | B19: — | C19: 10693.15 | D19: 15684.94 | E19: — | F19: 24454.52
A20: - Accumulated Depreciation | B20: — | C20: 3285.88 | D20: 4709.64 | E20: — | F20: 9621.09
A21: + LT Investments & Receivables | B21: 274.33 | C21: 3772.39 | D21: 4205.89 | E21: 6295.06 | F21: 6124.67
A22: + LT Investments | B22: 274.33 | C22: 3772.39 | D22: 4205.89 | E22: 6295.06 | F22: 6124.67
A23: + Other LT Assets | B23: 3061.17 | C23: 6665.84 | D23: 2491.81 | E23: 22863.16 | F23: 21546.17
A24: + Total Intangible Assets | B24: 294.42 | C24: 348.29 | D24: 326.03 | E24: 17373.62 | F24: 15347.34
A25: + Goodwill | B25: 163.8 | C25: 186.4 | D25: 186.48 | E25: 13799.04 | F25: 13620.7
A26: + Other Intangible Assets | B26: 130.62 | C26: 161.89 | D26: 139.55 | E26: 3574.58 | F26: 1726.64
A27: + Deferred Tax Assets | B27: 596.45 | C27: 1050.15 | D27: 1231.69 | E27: — | F27: 229.02
A28: + Investments in Affiliates | B28: — | C28: 0 | D28: — | E28: 0 | F28: 0
A29: + Misc LT Assets | B29: 2170.3 | C29: 5267.4 | D29: 934.09 | E29: 5489.54 | F29: 5969.81
A30: Total Noncurrent Assets | B30: 7929.54 | C30: 17845.5 | D30: 17673 | E30: 42908.24 | F30: 42504.27
A31: Total Assets | B31: 40625.45 | C31: 43573.08 | D31: 45977.98 | E31: 82508 | F31: 111892.85
A33: Liabilities & Shareholders' Equity
A34: + Payables & Accruals | B34: 1582.39 | C34: 2733.5 | D34: 4422.3 | E34: 8345 | F34: 7873.55
A35: + Accounts Payable | B35: 0.61 | C35: 7.97 | D35: 20.52 | E35: 8345 | F35: 7873.55
A36: + Other Payables & Accruals | B36: 1581.78 | C36: 2725.53 | D36: 4401.78 | E36: — | F36: —
A37: + ST Debt | B37: 1324.4 | C37: 2677.79 | D37: 3314.5 | E37: 4111.56 | F37: 2747.36
A38: + ST Borrowings | B38: 579.97 | C38: 1570.13 | D38: 1697.34 | E38: 2355.28 | F38: 844.67
A39: + ST Lease Liabilities | B39: 744.43 | C39: 1107.66 | D39: 1617.16 | E39: 1756.28 | F39: 1902.69
A40: + Other ST Liabilities | B40: 920.76 | C40: 1421.84 | D40: 1799.52 | E40: 2562.44 | F40: 2189.9
A41: + Deferred Tax Liabilities | B41: 0 | C41: 1.24 | D41: 1.2 | E41: 0 | F41: 0
...
